<mujoco model="right_shadow_hand">
  <compiler angle="radian" meshdir="assets" autolimits="true"/>

  <option timestep="0.01" iterations="10" ls_iterations="50">
    <flag eulerdamp="disable"/>
  </option>

  <default>
    <position dampratio="1.0"/>
    <default class="right_hand">
      <geom density="800" condim="1" contype="0" conaffinity="0"/>
      <position kp="300" dampratio="1.0"/>
      <joint damping="0.0" armature="1.0" axis="1 0 0" frictionloss="0.0"/>
      <site size="0.005" type="sphere" rgba="1 0 0 1" group="3"/>

      <mesh scale="0.001 0.001 0.001"/>

      <!-- <default class="wrist">
        <joint damping="0.5"/>
        <default class="wrist_y">
          <joint axis="0 1 0" range="-0.523599 0.174533"/>
          <position ctrlrange="-0.523599 0.174533" forcerange="-10 10"/>
        </default>
        <default class="wrist_x">
          <joint range="-0.698132 0.488692"/>
          <position ctrlrange="-0.698132 0.488692" forcerange="-5 5"/>
        </default>
      </default> -->

      <default class="thumb">
        <default class="thbase">
          <joint axis="0 0 -1" range="-1.0472 1.0472"/>
          <position ctrlrange="-1.0472 1.0472" forcerange="-3 3"/>
        </default>
        <default class="thproximal">
          <joint range="0 1.22173"/>
          <position ctrlrange="0 1.22173" forcerange="-2 2"/>
        </default>
        <default class="thhub">
          <joint range="-0.20944 0.20944"/>
          <position ctrlrange="-0.20944 0.20944"/>
        </default>
        <default class="thmiddle">
          <joint axis="0 -1 0" range="-0.698132 0.698132"/>
          <position ctrlrange="-0.698132 0.698132"/>
        </default>
        <default class="thdistal">
          <joint range="-0.261799 1.5708"/>
          <position ctrlrange="-0.261799 1.5708"/>
        </default>
      </default>

      <default class="metacarpal">
        <joint axis="0.573576 0 0.819152" range="0 0.785398"/>
        <position ctrlrange="0 0.785398"/>
      </default>
      <default class="knuckle">
        <joint axis="0 -1 0" range="-0.349066 0.349066"/>
        <position ctrlrange="-0.349066 0.349066"/>
      </default>
      <default class="proximal">
        <joint range="-0.261799 1.5708"/>
        <position ctrlrange="-0.261799 1.5708"/>
      </default>
      <default class="middle_distal">
        <joint range="0 1.5708"/>
        <position ctrlrange="0 3.1415"/>
      </default>

      <default class="plastic">
        <geom solimp="0.5 0.99 0.0001" solref="0.005 1"/>
        <default class="plastic_visual">
          <geom type="mesh" material="black" contype="0" conaffinity="0" group="2"/>
        </default>
        <default class="plastic_collision">
          <geom group="3" mass="0" condim="1" contype="0" conaffinity="0" />
        </default>
      </default>
    </default>
  </default>

  <visual>
    <headlight diffuse="0.6 0.6 0.6" ambient="0.1 0.1 0.1" specular="0.9 0.9 0.9" />
    <rgba haze="0.15 0.25 0.35 1" />
    <global azimuth="140" elevation="-20" />
  </visual>

  <asset>
    <texture type="skybox" builtin="gradient" rgb1="1 1 1" rgb2="1 1 1" width="512"
      height="3072" />
    <texture type="2d" name="right_groundplane" builtin="checker" mark="edge" rgb1="1 1 1"
      rgb2="1 1 1"
      markrgb="1 1 1" width="300" height="300" />
    <material name="right_groundplane" texture="right_groundplane" texuniform="true"
      texrepeat="5 5"
      reflectance="1" />

    <material name="black" specular="0.5" shininess="0.25" rgba="0.16355 0.16355 0.16355 1"/>
    <material name="gray" specular="0.0" shininess="0.25" rgba="0.80848 0.80848 0.80848 1"/>
    <material name="metallic" specular="0" shininess="0.25" rgba="0.9 0.9 0.9 1"/>

    <mesh name="forearm_0" class="right_hand" file="forearm_0.obj" scale="0.001 0.001 0.001"/>
    <mesh name="forearm_1" class="right_hand" file="forearm_1.obj" scale="0.001 0.001 0.001"/>
    <mesh name="forearm_collision" class="right_hand" file="forearm_collision.obj" scale="0.001 0.001 0.001"/>
    <mesh name="wrist" class="right_hand" file="wrist.obj" scale="0.001 0.001 0.001"/>
    <mesh name="palm" class="right_hand" file="palm.obj" scale="0.001 0.001 0.001"/>
    <mesh name="f_knuckle" class="right_hand" file="f_knuckle.obj" scale="0.001 0.001 0.001"/>
    <mesh name="f_proximal" class="right_hand" file="f_proximal.obj" scale="0.001 0.001 0.001"/>
    <mesh name="f_middle" class="right_hand" file="f_middle.obj" scale="0.001 0.001 0.001"/>
    <mesh name="f_distal_pst" class="right_hand" file="f_distal_pst.obj" scale="0.001 0.001 0.001"/>
    <mesh name="lf_metacarpal" class="right_hand" file="lf_metacarpal.obj" scale="0.001 0.001 0.001"/>
    <mesh name="th_proximal" class="right_hand" file="th_proximal.obj" scale="0.001 0.001 0.001"/>
    <mesh name="th_middle" class="right_hand" file="th_middle.obj" scale="0.001 0.001 0.001"/>
    <mesh name="th_distal_pst" class="right_hand" file="th_distal_pst.obj" scale="0.001 0.001 0.001"/>
  </asset>

  <worldbody>
    <light pos="0 0 3.5" dir="0 0 -1" directional="false"/>
    <body name="right_forearm" childclass="right_hand" quat="0 1 0 1" gravcomp="1">
      <inertial mass="3" pos="0 0 0.09" diaginertia="0.0138 0.0138 0.00744"/>
      <geom name="right_forearm_0_visual" class="plastic_visual" mesh="forearm_0" material="gray" group="1"/>
      <geom name="right_forearm_1_visual" class="plastic_visual" mesh="forearm_1" group="1"/>
      <!-- <geom name="collision_hand_right_forearm_0" class="plastic_collision" type="mesh"
        mesh="forearm_collision"/> -->
      <geom name="collision_hand_right_forearm_1" class="plastic_collision" size="0.035 0.035 0.035"
        pos="0.01 0.0 0.181" quat="0.380188 0.924909 0 0" type="box"/>

      <joint name="right_pos_x" type="slide" axis="1 0 0" range="-1.0 1.0"/>
      <joint name="right_pos_y" type="slide" axis="0 1 0" range="-1.0 1.0"/>
      <joint name="right_pos_z" type="slide" axis="0 0 1" range="-1.0 1.0"/>
      <joint name="right_rot_x" type="hinge" axis="1 0 0" range="-6.28 6.28"/>
      <joint name="right_rot_y" type="hinge" axis="0 1 0" range="-6.28 6.28"/>
      <joint name="right_rot_z" type="hinge" axis="0 0 1" range="-6.28 6.28"/>

      <body name="right_wrist" pos="0.01 0 0.21301" quat="1 0 0 1">
        <inertial mass="0.1" pos="0 0 0.029" quat="0.5 0.5 0.5 0.5"
          diaginertia="6.4e-05 4.38e-05 3.5e-05"/>
        <geom name="right_wrist_visual" class="plastic_visual" mesh="wrist" material="metallic" group="1"/>
        <geom name="collision_hand_right_wrist_0" size="0.0135 0.015" quat="0.499998 0.5 0.5 -0.500002" type="cylinder"
          class="plastic_collision"/>
        <geom name="collision_hand_right_wrist_1" size="0.011 0.005" pos="-0.026 0 0.034" quat="1 0 1 0" type="cylinder"
          class="plastic_collision"/>
        <geom name="collision_hand_right_wrist_2" size="0.011 0.005" pos="0.031 0 0.034" quat="1 0 1 0" type="cylinder"
          class="plastic_collision"/>
        <geom name="collision_hand_right_wrist_3" size="0.0135 0.009 0.005" pos="-0.021 0 0.011" quat="0.923879 0 0.382684 0"
          type="box" class="plastic_collision"/>
        <geom name="collision_hand_right_wrist_4" size="0.0135 0.009 0.005" pos="0.026 0 0.01" quat="0.923879 0 -0.382684 0"
          type="box" class="plastic_collision"/>
        <body name="right_palm" pos="0 0 0.034">
          <inertial mass="0.3" pos="0 0 0.035" quat="1 0 0 1"
            diaginertia="0.0005287 0.0003581 0.000191"/>
          <site name="grasp_site" pos="0.035 0 0.09" group="4"/>
          <site name="right_palm" pos="0.035 0 0.09" type="box" size="0.01 0.02 0.03" quat="1 0 0 -1"
            group="3"/>
          <geom name="right_palm_visual" class="plastic_visual" mesh="palm" group="1"/>
          <geom name="collision_hand_right_palm_0" size="0.031 0.0035 0.049"
            pos="0.011 0.0085 0.038" type="box" class="plastic_collision"/>
          <geom name="collision_hand_right_palm_1" size="0.018 0.0085 0.049" pos="-0.002 -0.0035 0.038" type="box"
            class="plastic_collision"/>
          <geom name="collision_hand_right_palm_2" size="0.013 0.0085 0.005" pos="0.029 -0.0035 0.082" type="box"
            class="plastic_collision"/>
          <geom name="collision_hand_right_palm_3" size="0.013 0.007 0.009" pos="0.0265 -0.001 0.07"
            quat="0.987241 0.0990545 0.0124467 0.124052" type="box" class="plastic_collision"/>
          <geom name="collision_hand_right_palm_4" size="0.0105 0.0135 0.012" pos="0.0315 -0.0085 0.001" type="box"
            class="plastic_collision"/>
          <geom name="collision_hand_right_palm_5" size="0.011 0.0025 0.015" pos="0.0125 -0.015 0.004"
            quat="0.971338 0 0 -0.237703" type="box" class="plastic_collision"/>
          <geom name="collision_hand_right_palm_6" size="0.009 0.012 0.002" pos="0.011 0 0.089" type="box" class="plastic_collision"/>
          <geom name="collision_hand_right_palm_7" size="0.01 0.012 0.02" pos="-0.03 0 0.009" type="box" class="plastic_collision"/>
          <body name="right_index_knuckle" pos="0.033 0 0.095">
            <inertial mass="0.008" pos="0 0 0" quat="0.5 0.5 -0.5 0.5"
              diaginertia="3.2e-07 2.6e-07 2.6e-07"/>
            <joint name="right_index_knuckle_joint" class="knuckle"/>
            <geom name="right_index_knuckle_visual" pos="0 0 0.0005" class="plastic_visual" mesh="f_knuckle" material="metallic" group="1"/>
            <geom name="collision_hand_right_index_knuckle_0" size="0.009 0.009" quat="1 0 1 0" type="cylinder" class="plastic_collision"/>
            <body name="right_index_proximal">
              <inertial mass="0.03" pos="0 0 0.0225" quat="1 0 0 1"
                diaginertia="1e-05 9.8e-06 1.8e-06"/>
              <joint name="right_index_proximal_joint" class="proximal"/>
              <geom name="right_index_proximal_visual" class="plastic_visual" mesh="f_proximal" group="1"/>
              <geom name="collision_hand_right_index_proximal_0" size="0.009 0.02" pos="0 0 0.025" type="capsule" class="plastic_collision"/>
              <body name="right_index_middle" pos="0 0 0.045">
                <inertial mass="0.017" pos="0 0 0.0125" quat="1 0 0 1"
                  diaginertia="2.7e-06 2.6e-06 8.7e-07"/>
                <joint name="right_index_middle_joint" class="middle_distal"/>
                <geom name="right_index_middle_visual" class="plastic_visual" mesh="f_middle" group="1"/>
                <geom name="collision_hand_right_index_middle_0" size="0.009 0.0125" pos="0 0 0.0125" type="capsule"
                  class="plastic_collision"/>
                <body name="right_index_distal" pos="0 0 0.025">
                  <inertial mass="0.013" pos="0 0 0.0130769" quat="1 0 0 1"
                    diaginertia="1.28092e-06 1.12092e-06 5.3e-07"/>
                  <joint name="right_index_distal_joint" class="middle_distal"/>
                  <site name="right_index_tip" pos="0 0 0.025" group="3"/>
                  <site name="track_hand_right_index_tip" pos="0 0 0.025"/>
                  <site name="trace_hand_right_index_tip" pos="0 0 0.025"/>
                  <geom name="right_index_distal_visual" class="plastic_visual" mesh="f_distal_pst" group="1"/>
                  <geom name="collision_hand_right_index_0" class="plastic_collision" type="mesh"
                    mesh="f_distal_pst"/>
                </body>
              </body>
            </body>
          </body>
          <body name="right_middle_knuckle" pos="0.011 0 0.099">
            <inertial mass="0.008" pos="0 0 0" quat="0.5 0.5 -0.5 0.5"
              diaginertia="3.2e-07 2.6e-07 2.6e-07"/>
            <joint name="right_middle_knuckle_joint" class="knuckle"/>
            <geom name="right_middle_knuckle_visual" pos="0 0 0.0005" class="plastic_visual" mesh="f_knuckle" material="metallic" group="1"/>
            <geom name="collision_hand_right_middle_knuckle_0" size="0.009 0.009" quat="1 0 1 0" type="cylinder" class="plastic_collision"/>
            <body name="right_middle_proximal">
              <inertial mass="0.03" pos="0 0 0.0225" quat="1 0 0 1"
                diaginertia="1e-05 9.8e-06 1.8e-06"/>
              <joint name="right_middle_proximal_joint" class="proximal"/>
              <geom name="right_middle_proximal_visual" class="plastic_visual" mesh="f_proximal" group="1"/>
              <geom name="collision_hand_right_middle_proximal_0" size="0.009 0.02" pos="0 0 0.025" type="capsule" class="plastic_collision"/>
              <body name="right_middle_middle" pos="0 0 0.045">
                <inertial mass="0.017" pos="0 0 0.0125" quat="1 0 0 1"
                  diaginertia="2.7e-06 2.6e-06 8.7e-07"/>
                <joint name="right_middle_middle_joint" class="middle_distal"/>
                <geom name="right_middle_middle_visual" class="plastic_visual" mesh="f_middle" group="1"/>
                <geom name="collision_hand_right_middle_middle_0" size="0.009 0.0125" pos="0 0 0.0125" type="capsule"
                  class="plastic_collision"/>
                <body name="right_middle_distal" pos="0 0 0.025">
                  <inertial mass="0.013" pos="0 0 0.0130769" quat="1 0 0 1"
                    diaginertia="1.28092e-06 1.12092e-06 5.3e-07"/>
                  <joint name="right_middle_distal_joint" class="middle_distal"/>
                  <site name="right_middle_tip" pos="0 0 0.025" group="3"/>
                  <site name="track_hand_right_middle_tip" pos="0 0 0.025"/>
                  <site name="trace_hand_right_middle_tip" pos="0 0 0.025"/>
                  <geom name="right_middle_distal_visual" class="plastic_visual" mesh="f_distal_pst" group="1"/>
                  <geom name="collision_hand_right_middle_0" class="plastic_collision" type="mesh"
                    mesh="f_distal_pst"/>
                </body>
              </body>
            </body>
          </body>
          <body name="right_ring_knuckle" pos="-0.011 0 0.095">
            <inertial mass="0.008" pos="0 0 0" quat="0.5 0.5 -0.5 0.5"
              diaginertia="3.2e-07 2.6e-07 2.6e-07"/>
            <joint name="right_ring_knuckle_joint" class="knuckle" axis="0 1 0"/>
            <geom name="right_ring_knuckle_visual" pos="0 0 0.0005" class="plastic_visual" mesh="f_knuckle" material="metallic" group="1"/>
            <geom name="collision_hand_right_ring_knuckle_0" size="0.009 0.009" quat="1 0 1 0" type="cylinder" class="plastic_collision"/>
            <body name="right_ring_proximal">
              <inertial mass="0.03" pos="0 0 0.0225" quat="1 0 0 1"
                diaginertia="1e-05 9.8e-06 1.8e-06"/>
              <joint name="right_ring_proximal_joint" class="proximal"/>
              <geom name="right_ring_proximal_visual" class="plastic_visual" mesh="f_proximal" group="1"/>
              <geom name="collision_hand_right_ring_proximal_0" size="0.009 0.02" pos="0 0 0.025" type="capsule" class="plastic_collision"/>
              <body name="right_ring_middle" pos="0 0 0.045">
                <inertial mass="0.017" pos="0 0 0.0125" quat="1 0 0 1"
                  diaginertia="2.7e-06 2.6e-06 8.7e-07"/>
                <joint name="right_ring_middle_joint" class="middle_distal"/>
                <geom name="right_ring_middle_visual" class="plastic_visual" mesh="f_middle" group="1"/>
                <geom name="collision_hand_right_ring_middle_0" size="0.009 0.0125" pos="0 0 0.0125" type="capsule"
                  class="plastic_collision"/>
                <body name="right_ring_distal" pos="0 0 0.025">
                  <inertial mass="0.013" pos="0 0 0.0130769" quat="1 0 0 1"
                    diaginertia="1.28092e-06 1.12092e-06 5.3e-07"/>
                  <joint name="right_ring_distal_joint" class="middle_distal"/>
                  <site name="right_ring_tip" pos="0 0 0.025" group="3"/>
                  <site name="track_hand_right_ring_tip" pos="0 0 0.025"/>
                  <site name="trace_hand_right_ring_tip" pos="0 0 0.025"/>
                  <geom name="right_ring_distal_visual" class="plastic_visual" mesh="f_distal_pst" group="1"/>
                  <geom name="collision_hand_right_ring_0" class="plastic_collision" type="mesh"
                    mesh="f_distal_pst"/>
                </body>
              </body>
            </body>
          </body>
          <body name="right_pinky_metacarpal" pos="-0.033 0 0.02071">
            <inertial mass="0.03" pos="0 0 0.04" quat="1 0 0 1"
              diaginertia="1.638e-05 1.45e-05 4.272e-06"/>
            <joint name="right_pinky_metacarpal_joint" class="metacarpal"/>
            <geom name="right_pinky_metacarpal_visual" class="plastic_visual" mesh="lf_metacarpal" group="1"/>
            <geom name="collision_hand_right_pinky_metacarpal_0" size="0.011 0.012 0.025" pos="0.002 0 0.033" type="box"
              class="plastic_collision"/>
            <body name="right_pinky_knuckle" pos="0 0 0.06579">
              <inertial mass="0.008" pos="0 0 0" quat="0.5 0.5 -0.5 0.5"
                diaginertia="3.2e-07 2.6e-07 2.6e-07"/>
              <joint name="right_pinky_knuckle_joint" class="knuckle" axis="0 1 0"/>
              <geom name="right_pinky_knuckle_visual" pos="0 0 0.0005" class="plastic_visual" mesh="f_knuckle" material="metallic" group="1"/>
              <geom name="collision_hand_right_pinky_knuckle_0" size="0.009 0.009" quat="1 0 1 0" type="cylinder" class="plastic_collision"/>
              <body name="right_pinky_proximal">
                <inertial mass="0.03" pos="0 0 0.0225" quat="1 0 0 1"
                  diaginertia="1e-05 9.8e-06 1.8e-06"/>
                <joint name="right_pinky_proximal_joint" class="proximal"/>
                <geom name="right_pinky_proximal_visual" class="plastic_visual" mesh="f_proximal" group="1"/>
                <geom name="collision_hand_right_pinky_proximal_0" size="0.009 0.02" pos="0 0 0.025" type="capsule" class="plastic_collision"/>
                <body name="right_pinky_middle" pos="0 0 0.045">
                  <inertial mass="0.017" pos="0 0 0.0125" quat="1 0 0 1"
                    diaginertia="2.7e-06 2.6e-06 8.7e-07"/>
                  <joint name="right_pinky_middle_joint" class="middle_distal"/>
                  <geom name="right_pinky_middle_visual" class="plastic_visual" mesh="f_middle" group="1"/>
                  <geom name="collision_hand_right_pinky_middle_0" size="0.009 0.0125" pos="0 0 0.0125" type="capsule"
                    class="plastic_collision"/>
                  <body name="right_pinky_distal" pos="0 0 0.025">
                    <inertial mass="0.013" pos="0 0 0.0130769" quat="1 0 0 1"
                      diaginertia="1.28092e-06 1.12092e-06 5.3e-07"/>
                    <joint name="right_pinky_distal_joint" class="middle_distal"/>
                    <site name="right_pinky_tip" pos="0 0 0.025" group="3"/>
                    <site name="track_hand_right_pinky_tip" pos="0 0 0.025"/>
                    <site name="trace_hand_right_pinky_tip" pos="0 0 0.025"/>
                    <geom name="right_pinky_distal_visual" class="plastic_visual" mesh="f_distal_pst" group="1"/>
                    <geom name="collision_hand_right_pinky_0" class="plastic_collision" type="mesh"
                      mesh="f_distal_pst"/>
                  </body>
                </body>
              </body>
            </body>
          </body>
          <body name="right_thumb_base" pos="0.034 -0.00858 0.029" quat="0.92388 0 0.382683 0">
            <inertial mass="0.01" pos="0 0 0" diaginertia="1.6e-07 1.6e-07 1.6e-07"/>
            <joint name="right_thumb_base_joint" class="thbase"/>
            <geom name="collision_hand_right_thumb_base_0" class="plastic_collision" size="0.013"/>
            <body name="right_thumb_proximal">
              <inertial mass="0.04" pos="0 0 0.019" diaginertia="1.36e-05 1.36e-05 3.13e-06"/>
              <joint name="right_thumb_proximal_joint" class="thproximal"/>
              <geom name="right_thumb_proximal_visual" class="plastic_visual" mesh="th_proximal" group="1"/>
              <geom name="collision_hand_right_thumb_proximal_0" class="plastic_collision" size="0.0105 0.009" pos="0 0 0.02" type="capsule"/>
              <body name="right_thumb_hub" pos="0 0 0.038">
                <inertial mass="0.005" pos="0 0 0" diaginertia="1e-06 1e-06 3e-07"/>
                <joint name="right_thumb_hub_joint" class="thhub"/>
                <geom name="collision_hand_right_thumb_hub_0" size="0.011" class="plastic_collision"/>
                <body name="right_thumb_middle">
                  <inertial mass="0.02" pos="0 0 0.016" diaginertia="5.1e-06 5.1e-06 1.21e-06"/>
                  <joint name="right_thumb_middle_joint" class="thmiddle"/>
                  <geom name="right_thumb_middle_visual" class="plastic_visual" mesh="th_middle" group="1"/>
                  <geom name="collision_hand_right_thumb_middle_0" size="0.009 0.009" pos="0 0 0.012" type="capsule" class="plastic_collision"/>
                  <geom name="collision_hand_right_thumb_middle_1" size="0.01" pos="0 0 0.03" class="plastic_collision"/>
                  <body name="right_thumb_distal" pos="0 0 0.032" quat="1 0 0 -1">
                    <inertial mass="0.017" pos="0 0 0.0145588" quat="1 0 0 1"
                      diaginertia="2.37794e-06 2.27794e-06 1e-06"/>
                    <joint name="right_thumb_distal_joint" class="thdistal"/>
                    <site name="right_thumb_tip" pos="0 0 0.025" group="3"/>
                    <site name="track_hand_right_thumb_tip" pos="0 0 0.025"/>
                    <site name="trace_hand_right_thumb_tip" pos="0 0 0.025"/>
                    <geom name="right_thumb_distal_visual" class="plastic_visual" mesh="th_distal_pst" group="1"/>
                    <geom name="collision_hand_right_thumb_0" class="plastic_collision" type="mesh"
                      mesh="th_distal_pst"/>
                  </body>
                </body>
              </body>
            </body>
          </body>
        </body>
      </body>
    </body>
  </worldbody>

  <actuator>
    <position name="right_pos_x_position" joint="right_pos_x" kp="1000"/>
    <position name="right_pos_y_position" joint="right_pos_y" kp="1000"/>
    <position name="right_pos_z_position" joint="right_pos_z" kp="1000"/>
    <position name="right_rot_x_position" joint="right_rot_x" kp="1000"/>
    <position name="right_rot_y_position" joint="right_rot_y" kp="1000"/>
    <position name="right_rot_z_position" joint="right_rot_z" kp="1000"/>
    <position name="right_index_knuckle_position" joint="right_index_knuckle_joint" class="knuckle"/>
    <position name="right_index_proximal_position" joint="right_index_proximal_joint" class="proximal"/>
    <position name="right_index_middle_position" joint="right_index_middle_joint" class="middle_distal"/>
    <position name="right_index_distal_position" joint="right_index_distal_joint" class="middle_distal"/>
    <position name="right_middle_knuckle_position" joint="right_middle_knuckle_joint" class="knuckle"/>
    <position name="right_middle_proximal_position" joint="right_middle_proximal_joint" class="proximal"/>
    <position name="right_middle_middle_position" joint="right_middle_middle_joint" class="middle_distal"/>
    <position name="right_middle_distal_position" joint="right_middle_distal_joint" class="middle_distal"/>
    <position name="right_ring_knuckle_position" joint="right_ring_knuckle_joint" class="knuckle"/>
    <position name="right_ring_proximal_position" joint="right_ring_proximal_joint" class="proximal"/>
    <position name="right_ring_middle_position" joint="right_ring_middle_joint" class="middle_distal"/>
    <position name="right_ring_distal_position" joint="right_ring_distal_joint" class="middle_distal"/>
    <position name="right_pinky_metacarpal_position" joint="right_pinky_metacarpal_joint" class="metacarpal"/>
    <position name="right_pinky_knuckle_position" joint="right_pinky_knuckle_joint" class="knuckle"/>
    <position name="right_pinky_proximal_position" joint="right_pinky_proximal_joint" class="proximal"/>
    <position name="right_pinky_middle_position" joint="right_pinky_middle_joint" class="middle_distal"/>
    <position name="right_pinky_distal_position" joint="right_pinky_distal_joint" class="middle_distal"/>
    <position name="right_thumb_base_position" joint="right_thumb_base_joint" class="thbase"/>
    <position name="right_thumb_proximal_position" joint="right_thumb_proximal_joint" class="thproximal"/>
    <position name="right_thumb_hub_position" joint="right_thumb_hub_joint" class="thhub"/>
    <position name="right_thumb_middle_position" joint="right_thumb_middle_joint" class="thmiddle"/>
    <position name="right_thumb_distal_position" joint="right_thumb_distal_joint" class="thdistal"/>
  </actuator>
</mujoco>
